<?xml version="1.0"?>
<robot xmlns:xacro="http://www.ros.org/wiki/xacro" name="gripper">
    <xacro:macro name="gripper" params="prefix *joint">
        <link name="gripper_base">
            <inertial>
                <origin xyz="-0.00075 -0.037 0.03" rpy="0.0 ${pi/2} 0.0"/>
                <mass value="0.0"/>
                <inertia ixx="0.0" ixy="0.0" ixz="0.0" iyy="0.0" iyz="0.0" izz="0.0"/>
            </inertial>
            <visual>
                <origin xyz="-0.00075 -0.037 0.03" rpy="0.0 ${pi/2} 0.0"/>
                <geometry>
                    <mesh filename="package://strawberry_picking_rpi_description/meshes/gripper_palm.stl" scale="0.001 0.001 0.001"/>
                </geometry>
                <material name="aluminum"/>
            </visual>
            <collision>
                <origin xyz="-0.00075 -0.037 0.03" rpy="0.0 ${pi/2} 0.0"/>
                <geometry>
                    <mesh filename="package://strawberry_picking_rpi_description/meshes/gripper_palm.stl" scale="0.001 0.001 0.001"/>
                </geometry>
            </collision>
        </link>

        <link name="gripper_palm_to_finger_large_lo">
            <inertial>
                <origin xyz="0.0 0.0 0.0" rpy="${pi/2} ${pi} ${pi/2}"/>
                <mass value="0.0"/>
                <inertia ixx="0.0" ixy="0.0" ixz="0.0" iyy="0.0" iyz="0.0" izz="0.0"/>
            </inertial>
            <visual>
                <origin xyz="-0.00075 0.0 0.0" rpy="${pi/2} ${pi} ${pi/2}"/>
                <geometry>
                    <mesh filename="package://strawberry_picking_rpi_description/meshes/gripper_palm_to_finger_large_lo.stl" scale="0.001 0.001 0.001"/>
                </geometry>
                <material name="aluminum"/>
            </visual>
        </link>
        <joint name="gripper_palm_to_finger_large_lo_to_gripper_base" type="revolute">
            <parent link="gripper_base"/>
            <child link="gripper_palm_to_finger_large_lo"/>
            <axis xyz="1 0 0"/>
            <limit lower="0.0" upper="1.1" velocity="50.0" effort="1000.0"/>
            <origin xyz="-0.002 -0.015 0.03" rpy="0 0 0"/>
        </joint>
        
        <link name="gripper_palm_to_finger_large">
            <inertial>
                <origin xyz="0.0 0.0 0.0" rpy="${pi/2} ${pi} ${pi/2}"/>
                <mass value="0.0"/>
                <inertia ixx="0.0" ixy="0.0" ixz="0.0" iyy="0.0" iyz="0.0" izz="0.0"/>
            </inertial>
            <visual>
                <origin xyz="-0.00075 0.0 0.0" rpy="${pi/2} ${pi} ${-pi/2}"/>
                <geometry>
                    <mesh filename="package://strawberry_picking_rpi_description/meshes/gripper_palm_to_finger_large.stl" scale="0.001 0.001 0.001"/>
                </geometry>
                <material name="aluminum"/>
            </visual>
        </link>
        <joint name="gripper_palm_to_finger_large_to_gripper_base" type="revolute">
            <parent link="gripper_base"/>
            <child link="gripper_palm_to_finger_large"/>
            <mimic joint="gripper_palm_to_finger_large_lo_to_gripper_base" multiplier="-1"/>
            <axis xyz="1 0 0"/>
            <limit lower="-3.14159" upper="3.14159" velocity="50.0" effort="1000.0"/>
            <origin xyz="0.0 0.012 0.03" rpy="0 0 0"/>
        </joint>

        <link name="gripper_palm_to_finger_small_left_over">
            <inertial>
                <origin xyz="0.0 0.0 0.0" rpy="${pi/2} ${pi} ${pi/2}"/>
                <mass value="0.0"/>
                <inertia ixx="0.0" ixy="0.0" ixz="0.0" iyy="0.0" iyz="0.0" izz="0.0"/>
            </inertial>
            <visual>
                <origin xyz="-0.00075 0.0 0.0" rpy="${pi/2} ${pi} ${-pi/2}"/>
                <geometry>
                    <mesh filename="package://strawberry_picking_rpi_description/meshes/gripper_palm_to_finger_small.stl" scale="0.001 0.001 0.001"/>
                </geometry>
                <material name="aluminum"/>
            </visual>
        </link>
        <joint name="gripper_palm_to_finger_small_left_over_to_gripper_base" type="revolute">
            <parent link="gripper_base"/>
            <child link="gripper_palm_to_finger_small_left_over"/>
            <axis xyz="1 0 0"/>
            <mimic joint="gripper_palm_to_finger_large_lo_to_gripper_base" multiplier="-1"/>
            <limit lower="-3.14159" upper="3.14159" velocity="50.0" effort="1000.0"/>
            <origin xyz="0.0 0.0068 0.052" rpy="0 0 0"/>
        </joint>
        <link name="gripper_palm_to_finger_small_left_under">
            <inertial>
                <origin xyz="0.0 0.0 0.0" rpy="${pi/2} ${pi} ${pi/2}"/>
                <mass value="0.0"/>
                <inertia ixx="0.0" ixy="0.0" ixz="0.0" iyy="0.0" iyz="0.0" izz="0.0"/>
            </inertial>
            <visual>
                <origin xyz="-0.00075 0.0 0.0" rpy="${pi/2} ${pi} ${-pi/2}"/>
                <geometry>
                    <mesh filename="package://strawberry_picking_rpi_description/meshes/gripper_palm_to_finger_small.stl" scale="0.001 0.001 0.001"/>
                </geometry>
                <material name="aluminum"/>
            </visual>
        </link>
        <joint name="gripper_palm_to_finger_small_left_under_to_gripper_base" type="revolute">
            <parent link="gripper_base"/>
            <child link="gripper_palm_to_finger_small_left_under"/>
            <axis xyz="1 0 0"/>
            <mimic joint="gripper_palm_to_finger_large_lo_to_gripper_base" multiplier="-1"/>
            <limit lower="-3.14159" upper="3.14159" velocity="50.0" effort="1000.0"/>
            <origin xyz="0.004 0.0068 0.052" rpy="0 0 0"/>
        </joint>
        
        <link name="gripper_palm_to_finger_small_right_over">
            <inertial>
                <origin xyz="0.0 0.0 0.0" rpy="${pi/2} ${pi} ${pi/2}"/>
                <mass value="0.0"/>
                <inertia ixx="0.0" ixy="0.0" ixz="0.0" iyy="0.0" iyz="0.0" izz="0.0"/>
            </inertial>
            <visual>
                <origin xyz="-0.00075 0.0 0.0" rpy="${pi/2} ${pi} ${-pi/2}"/>
                <geometry>
                    <mesh filename="package://strawberry_picking_rpi_description/meshes/gripper_palm_to_finger_small.stl" scale="0.001 0.001 0.001"/>
                </geometry>
                <material name="aluminum"/>
            </visual>
        </link>
        <joint name="gripper_palm_to_finger_small_right_over_to_gripper_base" type="revolute">
            <parent link="gripper_base"/>
            <child link="gripper_palm_to_finger_small_right_over"/>
            <axis xyz="1 0 0"/>
            <mimic joint="gripper_palm_to_finger_large_lo_to_gripper_base"/>
            <limit lower="-3.14159" upper="3.14159" velocity="50.0" effort="1000.0"/>
            <origin xyz="0.0 -0.0068 0.052" rpy="0 0 0"/>
        </joint>
        <link name="gripper_palm_to_finger_small_right_under">
            <inertial>
                <origin xyz="0.0 0.0 0.0" rpy="${pi/2} ${pi} ${pi/2}"/>
                <mass value="0.0"/>
                <inertia ixx="0.0" ixy="0.0" ixz="0.0" iyy="0.0" iyz="0.0" izz="0.0"/>
            </inertial>
            <visual>
                <origin xyz="-0.00075 0.0 0.0" rpy="${pi/2} ${pi} ${-pi/2}"/>
                <geometry>
                    <mesh filename="package://strawberry_picking_rpi_description/meshes/gripper_palm_to_finger_small.stl" scale="0.001 0.001 0.001"/>
                </geometry>
                <material name="aluminum"/>
            </visual>
        </link>
        <joint name="gripper_palm_to_finger_small_right_under_to_gripper_base" type="revolute">
            <parent link="gripper_base"/>
            <child link="gripper_palm_to_finger_small_right_under"/>
            <axis xyz="1 0 0"/>
            <mimic joint="gripper_palm_to_finger_large_lo_to_gripper_base"/>
            <limit lower="-3.14159" upper="3.14159" velocity="50.0" effort="1000.0"/>
            <origin xyz="0.004 -0.0068 0.052" rpy="0 0 0"/>
        </joint>

        <link name="finger_left">
            <inertial>
                <origin xyz="0.0 0.0 0.0" rpy="${pi/2} ${pi} ${pi/2}"/>
                <mass value="0.0"/>
                <inertia ixx="0.0" ixy="0.0" ixz="0.0" iyy="0.0" iyz="0.0" izz="0.0"/>
            </inertial>
            <visual>
                <origin xyz="-0.00075 -0.005 -0.005" rpy="${pi/2} ${-pi/2} ${-pi/2}"/>
                <geometry>
                    <mesh filename="package://strawberry_picking_rpi_description/meshes/finger.stl" scale="0.001 0.001 0.001"/>
                </geometry>
                <material name="aluminum"/>
            </visual>
            <collision>
                <origin xyz="-0.00075 -0.005 -0.005" rpy="${pi/2} ${-pi/2} ${-pi/2}"/>
                <geometry>
                    <mesh filename="package://strawberry_picking_rpi_description/meshes/finger.stl" scale="0.001 0.001 0.001"/>
                </geometry>
            </collision>
        </link>
        <joint name="finger_left_to_gripper_palm_to_finger_large" type="revolute">
            <parent link="gripper_palm_to_finger_large"/>
            <child link="finger_left"/>
            <axis xyz="1 0 0"/>
            <mimic joint="gripper_palm_to_finger_large_to_gripper_base" multiplier="-1"/>
            <limit lower="-3.14159" upper="3.14159" velocity="50.0" effort="1000.0"/>
            <origin xyz="0.002 0.0 0.0305" rpy="0.34 0 0"/>
        </joint>
        <link name="finger_right">
            <inertial>
                <origin xyz="0.0 0.0 0.0" rpy="${pi/2} ${pi} ${pi/2}"/>
                <mass value="0.0"/>
                <inertia ixx="0.0" ixy="0.0" ixz="0.0" iyy="0.0" iyz="0.0" izz="0.0"/>
            </inertial>
            <visual>
                <origin xyz="0.000 0.005 -0.005" rpy="${-pi/2} ${-pi/2} ${-pi/2}"/>
                <geometry>
                    <mesh filename="package://strawberry_picking_rpi_description/meshes/finger.stl" scale="0.001 0.001 0.001"/>
                </geometry>
                <material name="aluminum"/>
            </visual>
            <collision>
                <origin xyz="0.000 0.005 -0.005" rpy="${-pi/2} ${-pi/2} ${-pi/2}"/>
                <geometry>
                    <mesh filename="package://strawberry_picking_rpi_description/meshes/finger.stl" scale="0.001 0.001 0.001"/>
                </geometry>
            </collision>
        </link>
        <joint name="finger_right_to_gripper_palm_to_finger_large" type="revolute">
            <parent link="gripper_palm_to_finger_large_lo"/>
            <child link="finger_right"/>
            <axis xyz="1 0 0"/>
            <mimic joint="gripper_palm_to_finger_large_to_gripper_base"/>
            <limit lower="-3.14159" upper="3.14159" velocity="50.0" effort="1000.0"/>
            <origin xyz="0.002 0.0 0.0305" rpy="-0.38 0 0"/>
        </joint>

        <link name="gripper_servo">
            <inertial>
                <origin xyz="0.0 0.0 0.0" rpy="${pi/2} ${pi} ${-pi/2}"/>
                <mass value="0.0"/>
                <inertia ixx="0.0" ixy="0.0" ixz="0.0" iyy="0.0" iyz="0.0" izz="0.0"/>
            </inertial>
            <visual>
                <origin xyz="0.0275 -0.0095 0.0" rpy="${pi/2} ${pi} ${-pi/2}"/>
                <geometry>
                    <mesh filename="package://strawberry_picking_rpi_description/meshes/mg996r_servo_reversed.stl" scale="0.001 0.001 0.001"/>
                </geometry>
                <material name="aluminum"/>
            </visual>
        </link>
        <joint name="gripper_servo_to_gripper_base" type="fixed">
            <parent link="gripper_base"/>
            <child link="gripper_servo"/>
            <origin xyz="0.002 -0.015 0.0305" rpy="0.0 0 0"/>
        </joint>

        <xacro:insert_block name="joint"/>
    </xacro:macro>
</robot>