<?xml version="1.0" ?>
<!-- =================================================================================== -->
<!-- |    This document was autogenerated by xacro from strawberry_picking_rpi.urdf.xacro | -->
<!-- |    EDITING THIS FILE BY HAND IS NOT RECOMMENDED                                 | -->
<!-- =================================================================================== -->
<robot name="strawberry_picking_rpi">
  <material name="wood">
    <color rgba="0.6431372549019608 0.4549019607843137 0.28627450980392155 1.0"/>
    <texture filename=""/>
  </material>
  <material name="aluminum">
    <color rgba="0.5333333333333333 0.5450980392156862 0.5529411764705883 1.0"/>
  </material>
  <material name="black_plastic">
    <color rgba="0.058823529411764705 0.058823529411764705 0.07450980392156863 1.0"/>
  </material>
  <!-- the base link is the plank where the robot sits on -->
  <link name="base_link">
    <visual name="base_link">
      <origin rpy="0.0 0.0 0.0" xyz="0.0 0.0 0.0"/>
      <geometry>
        <box size="0.1                             0.1                             0.02"/>
      </geometry>
      <material name="wood"/>
    </visual>
    <collision>
      <origin rpy="0.0 0.0 0.0" xyz="0.0 0.0 0.0"/>
      <geometry>
        <box size="0.1                             0.1                             0.02"/>
      </geometry>
    </collision>
  </link>
  <link name="1_u_type_robot_waist_bracket">
    <inertial>
      <origin rpy="         0.0          0.0         0.0" xyz="         0.0         0.0225         0.014"/>
      <mass value="0.0"/>
      <inertia ixx="0.0" ixy="0.0" ixz="0.0" iyy="0.0" iyz="0.0" izz="0.0"/>
    </inertial>
    <visual>
      <origin rpy="         0.0          0.0         0.0" xyz="         0.0         0.0225         0.014"/>
      <geometry>
        <mesh filename="package://strawberry_picking_rpi_description/meshes/u_type_robot_waist_bracket.stl" scale="0.001 0.001 0.001"/>
      </geometry>
      <material name="aluminum"/>
    </visual>
    <collision>
      <origin rpy="         0.0          0.0         0.0" xyz="         0.0         0.0225         0.014"/>
      <geometry>
        <box size="0.09                                 0.045                                 0.028"/>
      </geometry>
    </collision>
  </link>
  <joint name="1_u_type_robot_waist_bracket_link_to_base_link" type="fixed">
    <origin rpy="         0.0          0.0         0.0" xyz="         0.0         0.0         0.01"/>
    <parent link="base_link"/>
    <child link="1_u_type_robot_waist_bracket"/>
  </joint>
  <link name="2_u_type_robot_waist_bracket">
    <inertial>
      <origin rpy="         0.0          0.0         0.0" xyz="         0.0         0.0225         0.014"/>
      <mass value="0.0"/>
      <inertia ixx="0.0" ixy="0.0" ixz="0.0" iyy="0.0" iyz="0.0" izz="0.0"/>
    </inertial>
    <visual>
      <origin rpy="         0.0          0.0         0.0" xyz="         0.0         0.0225         0.014"/>
      <geometry>
        <mesh filename="package://strawberry_picking_rpi_description/meshes/u_type_robot_waist_bracket.stl" scale="0.001 0.001 0.001"/>
      </geometry>
      <material name="aluminum"/>
    </visual>
    <collision>
      <origin rpy="         0.0          0.0         0.0" xyz="         0.0         0.0225         0.014"/>
      <geometry>
        <box size="0.09                                 0.045                                 0.028"/>
      </geometry>
    </collision>
  </link>
  <joint name="2_u_type_robot_waist_bracket_link_to_1_u_type_robot_waist_bracket" type="fixed">
    <origin rpy="         0.0          0.0         3.141592653589793" xyz="         0.0         0.0         0.0"/>
    <parent link="1_u_type_robot_waist_bracket"/>
    <child link="2_u_type_robot_waist_bracket"/>
  </joint>
  <link name="3_u_type_robot_waist_bracket">
    <inertial>
      <origin rpy="         1.5707963267948966         0.0         0.0" xyz="         0.0         0.0         0.0225"/>
      <mass value="0.0"/>
      <inertia ixx="0.0" ixy="0.0" ixz="0.0" iyy="0.0" iyz="0.0" izz="0.0"/>
    </inertial>
    <visual>
      <origin rpy="         1.5707963267948966         0.0         0.0" xyz="         0.0         0.0         0.0225"/>
      <geometry>
        <mesh filename="package://strawberry_picking_rpi_description/meshes/u_type_robot_waist_bracket.stl" scale="0.001 0.001 0.001"/>
      </geometry>
      <material name="aluminum"/>
    </visual>
    <collision>
      <origin rpy="         1.5707963267948966         0.0         0.0" xyz="         0.0         0.0         0.0225"/>
      <geometry>
        <box size="0.09                                 0.045                                 0.028"/>
      </geometry>
    </collision>
  </link>
  <joint name="3_u_type_robot_waist_bracket_link_to_1_u_type_robot_waist_bracket" type="fixed">
    <origin rpy="         0.0          0.0         0.0" xyz="         0.0         0.03025         0.028"/>
    <parent link="1_u_type_robot_waist_bracket"/>
    <child link="3_u_type_robot_waist_bracket"/>
  </joint>
  <link name="1_multi_functional_servo_bracket_with_servo">
    <inertial>
      <origin rpy="         0.0         0.0         3.141592653589793" xyz="         0.0          0.013300000000000001          0.01"/>
      <mass value="0.0"/>
      <inertia ixx="0.0" ixy="0.0" ixz="0.0" iyy="0.0" iyz="0.0" izz="0.0"/>
    </inertial>
    <visual name="">
      <origin rpy="         0.0         0.0         3.141592653589793" xyz="         0.0          0.013300000000000001          0.01"/>
      <geometry>
        <mesh filename="package://strawberry_picking_rpi_description/meshes/multi_functional_servo_bracket.stl" scale="0.001 0.001 0.001"/>
      </geometry>
      <material name="aluminum"/>
    </visual>
    <collision>
      <origin rpy="         0.0         0.0         3.141592653589793" xyz="         0.0          0.013300000000000001          0.01"/>
      <geometry>
        <box size="0.057                                 0.025                                 0.05"/>
      </geometry>
    </collision>
  </link>
  <link name="1_servo">
    <visual>
      <origin rpy="         0.0         0.0         3.141592653589793" xyz="         0.0          0.013300000000000001          0.01"/>
      <geometry>
        <mesh filename="package://strawberry_picking_rpi_description/meshes/mg996r_servo.stl" scale="0.001 0.001 0.001"/>
      </geometry>
      <material name="black_plastic"/>
    </visual>
  </link>
  <joint name="1_servo_to_1_multi_functional_servo_bracket_with_servo" type="fixed">
    <parent link="1_multi_functional_servo_bracket_with_servo"/>
    <child link="1_servo"/>
  </joint>
  <joint name="1_multi_functional_servo_bracket_with_servo_to_3_u_type_robot_waist_bracket" type="fixed">
    <origin rpy="             0.0              0.0             3.141592653589793" xyz="             0.0             -0.014             0.03025"/>
    <parent link="3_u_type_robot_waist_bracket"/>
    <child link="1_multi_functional_servo_bracket_with_servo"/>
  </joint>
  <link name="1_long_u_type_servo_bracket">
    <inertial>
      <origin rpy="         0.0         1.5707963267948966         0.0" xyz="         -0.052500000000000005         -0.01         -0.025500000000000002"/>
      <mass value="0.0"/>
      <inertia ixx="0.0" ixy="0.0" ixz="0.0" iyy="0.0" iyz="0.0" izz="0.0"/>
    </inertial>
    <visual name="">
      <origin rpy="         0.0         1.5707963267948966         0.0" xyz="         -0.052500000000000005         -0.01         -0.025500000000000002"/>
      <geometry>
        <mesh filename="package://strawberry_picking_rpi_description/meshes/long_u_type_servo_bracket.stl" scale="0.001 0.001 0.001"/>
      </geometry>
      <material name="aluminum"/>
    </visual>
    <collision>
      <origin rpy="         0.0         1.5707963267948966         0.0" xyz="         -0.052500000000000005         -0.01         -0.025500000000000002"/>
      <geometry>
        <mesh filename="package://strawberry_picking_rpi_description/meshes/long_u_type_servo_bracket.stl" scale="0.001 0.001 0.001"/>
      </geometry>
    </collision>
  </link>
  <joint name="DOF_1" type="revolute">
    <origin rpy="             0.0              0.0             -3.141592653589793" xyz="             0.0095             0.014             0.036000000000000004"/>
    <limit effort="1000" lower="0" upper="3.141592653589793" velocity="6.98133333333"/>
    <axis xyz="0.0 0.0 1"/>
    <parent link="1_multi_functional_servo_bracket_with_servo"/>
    <child link="1_long_u_type_servo_bracket"/>
  </joint>
  <link name="2_multi_functional_servo_bracket_with_servo">
    <inertial>
      <origin rpy="         0.0         0.0         0.0" xyz="         0.0         -0.014          0.009"/>
      <mass value="0.0"/>
      <inertia ixx="0.0" ixy="0.0" ixz="0.0" iyy="0.0" iyz="0.0" izz="0.0"/>
    </inertial>
    <visual name="">
      <origin rpy="         0.0         0.0         0.0" xyz="         0.0         -0.014          0.009"/>
      <geometry>
        <mesh filename="package://strawberry_picking_rpi_description/meshes/multi_functional_servo_bracket.stl" scale="0.001 0.001 0.001"/>
      </geometry>
      <material name="aluminum"/>
    </visual>
    <collision>
      <origin rpy="         0.0         0.0         0.0" xyz="         0.0         -0.014          0.009"/>
      <geometry>
        <box size="0.057                                 0.025                                 0.05"/>
      </geometry>
    </collision>
  </link>
  <link name="2_servo">
    <visual>
      <origin rpy="         0.0         0.0         0.0" xyz="         0.0         -0.014          0.009"/>
      <geometry>
        <mesh filename="package://strawberry_picking_rpi_description/meshes/mg996r_servo_reversed.stl" scale="0.001 0.001 0.001"/>
      </geometry>
      <material name="black_plastic"/>
    </visual>
  </link>
  <joint name="2_servo_to_2_multi_functional_servo_bracket_with_servo" type="fixed">
    <parent link="2_multi_functional_servo_bracket_with_servo"/>
    <child link="2_servo"/>
  </joint>
  <joint name="2_multi_functional_servo_bracket_with_servo_to_1_long_u_type_servo_bracket" type="fixed">
    <origin rpy="             1.5707963267948966             3.141592653589793             3.141592653589793" xyz="             -0.012             -0.011             0.003"/>
    <parent link="1_long_u_type_servo_bracket"/>
    <child link="2_multi_functional_servo_bracket_with_servo"/>
  </joint>
  <link name="2_long_u_type_servo_bracket">
    <inertial>
      <origin rpy="         0.0         1.5707963267948966         0.0" xyz="         -0.052500000000000005         -0.01         -0.0265"/>
      <mass value="0.0"/>
      <inertia ixx="0.0" ixy="0.0" ixz="0.0" iyy="0.0" iyz="0.0" izz="0.0"/>
    </inertial>
    <visual name="">
      <origin rpy="         0.0         1.5707963267948966         0.0" xyz="         -0.052500000000000005         -0.01         -0.0265"/>
      <geometry>
        <mesh filename="package://strawberry_picking_rpi_description/meshes/long_u_type_servo_bracket.stl" scale="0.001 0.001 0.001"/>
      </geometry>
      <material name="aluminum"/>
    </visual>
    <collision>
      <origin rpy="         0.0         1.5707963267948966         0.0" xyz="         -0.052500000000000005         -0.01         -0.0265"/>
      <geometry>
        <mesh filename="package://strawberry_picking_rpi_description/meshes/long_u_type_servo_bracket.stl" scale="0.001 0.001 0.001"/>
      </geometry>
    </collision>
  </link>
  <joint name="DOF_2" type="revolute">
    <origin rpy="             0.0              0.0             0.0" xyz="             0.0095             -0.014             0.036000000000000004"/>
    <limit effort="1000" lower="0" upper="3.141592653589793" velocity="6.98133333333"/>
    <axis xyz="0.0 0.0 1"/>
    <parent link="2_multi_functional_servo_bracket_with_servo"/>
    <child link="2_long_u_type_servo_bracket"/>
  </joint>
  <link name="3_long_u_type_servo_bracket">
    <inertial>
      <origin rpy="         0.0         -1.5707963267948966         0.0" xyz="         -0.053000000000000005         -0.0105         -0.025500000000000002"/>
      <mass value="0.0"/>
      <inertia ixx="0.0" ixy="0.0" ixz="0.0" iyy="0.0" iyz="0.0" izz="0.0"/>
    </inertial>
    <visual name="">
      <origin rpy="         0.0         -1.5707963267948966         0.0" xyz="         -0.053000000000000005         -0.0105         -0.025500000000000002"/>
      <geometry>
        <mesh filename="package://strawberry_picking_rpi_description/meshes/long_u_type_servo_bracket.stl" scale="0.001 0.001 0.001"/>
      </geometry>
      <material name="aluminum"/>
    </visual>
    <collision>
      <origin rpy="         0.0         -1.5707963267948966         0.0" xyz="         -0.053000000000000005         -0.0105         -0.025500000000000002"/>
      <geometry>
        <mesh filename="package://strawberry_picking_rpi_description/meshes/long_u_type_servo_bracket.stl" scale="0.001 0.001 0.001"/>
      </geometry>
    </collision>
  </link>
  <joint name="3_long_u_type_servo_bracket_to_2_long_u_type_servo_bracket" type="fixed">
    <origin rpy="             0.0              0.0             0.0" xyz="             0.0             0.0             0.0"/>
    <parent link="2_long_u_type_servo_bracket"/>
    <child link="3_long_u_type_servo_bracket"/>
  </joint>
  <link name="3_multi_functional_servo_bracket_with_servo">
    <inertial>
      <origin rpy="         0.0         0.0         3.141592653589793" xyz="         0.0095         0.0         -0.028"/>
      <mass value="0.0"/>
      <inertia ixx="0.0" ixy="0.0" ixz="0.0" iyy="0.0" iyz="0.0" izz="0.0"/>
    </inertial>
    <visual name="">
      <origin rpy="         0.0         0.0         3.141592653589793" xyz="         0.0095         0.0         -0.028"/>
      <geometry>
        <mesh filename="package://strawberry_picking_rpi_description/meshes/multi_functional_servo_bracket.stl" scale="0.001 0.001 0.001"/>
      </geometry>
      <material name="aluminum"/>
    </visual>
    <collision>
      <origin rpy="         0.0         0.0         3.141592653589793" xyz="         0.0095         0.0         -0.028"/>
      <geometry>
        <box size="0.057                                 0.025                                 0.05"/>
      </geometry>
    </collision>
  </link>
  <link name="3_servo">
    <visual>
      <origin rpy="         0.0         0.0         3.141592653589793" xyz="         0.0095         0.0         -0.028"/>
      <geometry>
        <mesh filename="package://strawberry_picking_rpi_description/meshes/mg996r_servo_reversed.stl" scale="0.001 0.001 0.001"/>
      </geometry>
      <material name="black_plastic"/>
    </visual>
  </link>
  <joint name="3_servo_to_3_multi_functional_servo_bracket_with_servo" type="fixed">
    <parent link="3_multi_functional_servo_bracket_with_servo"/>
    <child link="3_servo"/>
  </joint>
  <joint name="DOF_3" type="revolute">
    <origin rpy="             0.0             0.0             -2.5707963267948966" xyz="             -0.1055             0.0             0.0"/>
    <limit effort="1000" lower="0" upper="3.141592653589793" velocity="6.98133333333"/>
    <axis xyz="0.0 0.0 -1"/>
    <parent link="3_long_u_type_servo_bracket"/>
    <child link="3_multi_functional_servo_bracket_with_servo"/>
  </joint>
  <link name="1_l_type_servo_bracket">
    <inertial>
      <origin rpy="         0.0         0.0         0.0" xyz="         0.0         -0.0062         0.0105"/>
      <mass value="0.0"/>
      <inertia ixx="0.0" ixy="0.0" ixz="0.0" iyy="0.0" iyz="0.0" izz="0.0"/>
    </inertial>
    <visual name="">
      <origin rpy="         0.0         0.0         0.0" xyz="         0.0         -0.0062         0.0105"/>
      <geometry>
        <mesh filename="package://strawberry_picking_rpi_description/meshes/l_type_servo_bracket.stl" scale="0.001 0.001 0.001"/>
      </geometry>
      <material name="aluminum"/>
    </visual>
  </link>
  <joint name="1_l_type_servo_bracket_link_to_3_multi_functional_servo_bracket_with_servo" type="fixed">
    <origin rpy="         4.71238898038469          1.5707963267948966         0.0" xyz="         0.0205         -0.013500000000000002         -0.025"/>
    <parent link="3_multi_functional_servo_bracket_with_servo"/>
    <child link="1_l_type_servo_bracket"/>
  </joint>
  <link name="4_long_u_type_servo_bracket">
    <inertial>
      <origin rpy="         1.5707963267948966         0.0         0.0" xyz="         0.0         0.0         -0.008"/>
      <mass value="0.0"/>
      <inertia ixx="0.0" ixy="0.0" ixz="0.0" iyy="0.0" iyz="0.0" izz="0.0"/>
    </inertial>
    <visual name="">
      <origin rpy="         1.5707963267948966         0.0         0.0" xyz="         0.0         0.0         -0.008"/>
      <geometry>
        <mesh filename="package://strawberry_picking_rpi_description/meshes/long_u_type_servo_bracket.stl" scale="0.001 0.001 0.001"/>
      </geometry>
      <material name="aluminum"/>
    </visual>
    <collision>
      <origin rpy="         1.5707963267948966         0.0         0.0" xyz="         0.0         0.0         -0.008"/>
      <geometry>
        <mesh filename="package://strawberry_picking_rpi_description/meshes/long_u_type_servo_bracket.stl" scale="0.001 0.001 0.001"/>
      </geometry>
    </collision>
  </link>
  <joint name="4_long_u_type_servo_bracket_to_1_l_type_servo_bracket" type="fixed">
    <origin rpy="             0.0              0.0             0.0" xyz="             0.0             -0.025             0.0125"/>
    <parent link="1_l_type_servo_bracket"/>
    <child link="4_long_u_type_servo_bracket"/>
  </joint>
  <link name="4_multi_functional_servo_bracket_with_servo">
    <inertial>
      <origin rpy="         0.0         0.0         0.0" xyz="         0.0095         0.0         -0.025"/>
      <mass value="0.0"/>
      <inertia ixx="0.0" ixy="0.0" ixz="0.0" iyy="0.0" iyz="0.0" izz="0.0"/>
    </inertial>
    <visual name="">
      <origin rpy="         0.0         0.0         0.0" xyz="         0.0095         0.0         -0.025"/>
      <geometry>
        <mesh filename="package://strawberry_picking_rpi_description/meshes/multi_functional_servo_bracket.stl" scale="0.001 0.001 0.001"/>
      </geometry>
      <material name="aluminum"/>
    </visual>
    <collision>
      <origin rpy="         0.0         0.0         0.0" xyz="         0.0095         0.0         -0.025"/>
      <geometry>
        <box size="0.057                                 0.025                                 0.05"/>
      </geometry>
    </collision>
  </link>
  <link name="4_servo">
    <visual>
      <origin rpy="         0.0         0.0         0.0" xyz="         0.0095         0.0         -0.025"/>
      <geometry>
        <mesh filename="package://strawberry_picking_rpi_description/meshes/mg996r_servo.stl" scale="0.001 0.001 0.001"/>
      </geometry>
      <material name="black_plastic"/>
    </visual>
  </link>
  <joint name="4_servo_to_4_multi_functional_servo_bracket_with_servo" type="fixed">
    <parent link="4_multi_functional_servo_bracket_with_servo"/>
    <child link="4_servo"/>
  </joint>
  <joint name="DOF_4" type="revolute">
    <origin rpy="             0.0             -1.5707963267948966             0.0" xyz="             -0.025             -0.0525             0.002"/>
    <limit effort="1000" lower="0" upper="3.141592653589793" velocity="6.98133333333"/>
    <axis xyz="0.0 0.0 -1"/>
    <parent link="4_long_u_type_servo_bracket"/>
    <child link="4_multi_functional_servo_bracket_with_servo"/>
  </joint>
  <link name="5_multi_functional_servo_bracket_with_servo">
    <inertial>
      <origin rpy="         3.141592653589793         -1.5707963267948966         0.0" xyz="         0.007         0.0125         0.0"/>
      <mass value="0.0"/>
      <inertia ixx="0.0" ixy="0.0" ixz="0.0" iyy="0.0" iyz="0.0" izz="0.0"/>
    </inertial>
    <visual name="">
      <origin rpy="         3.141592653589793         -1.5707963267948966         0.0" xyz="         0.007         0.0125         0.0"/>
      <geometry>
        <mesh filename="package://strawberry_picking_rpi_description/meshes/multi_functional_servo_bracket.stl" scale="0.001 0.001 0.001"/>
      </geometry>
      <material name="aluminum"/>
    </visual>
    <collision>
      <origin rpy="         3.141592653589793         -1.5707963267948966         0.0" xyz="         0.007         0.0125         0.0"/>
      <geometry>
        <box size="0.057                                 0.025                                 0.05"/>
      </geometry>
    </collision>
  </link>
  <link name="5_servo">
    <visual>
      <origin rpy="         3.141592653589793         -1.5707963267948966         0.0" xyz="         0.007         0.0125         0.0"/>
      <geometry>
        <mesh filename="package://strawberry_picking_rpi_description/meshes/mg996r_servo_reversed.stl" scale="0.001 0.001 0.001"/>
      </geometry>
      <material name="black_plastic"/>
    </visual>
  </link>
  <joint name="5_servo_to_5_multi_functional_servo_bracket_with_servo" type="fixed">
    <parent link="5_multi_functional_servo_bracket_with_servo"/>
    <child link="5_servo"/>
  </joint>
  <joint name="5_multi_functional_servo_bracket_with_servo_to_4_multi_functional_servo_bracket_with_servo" type="fixed">
    <origin rpy="             0.0             0.0             0.0" xyz="             0.021             0.0125             -0.022000000000000002"/>
    <parent link="4_multi_functional_servo_bracket_with_servo"/>
    <child link="5_multi_functional_servo_bracket_with_servo"/>
  </joint>
  <link name="gripper_base">
    <inertial>
      <origin rpy="0.0 1.5707963267948966 0.0" xyz="-0.00075 -0.037 0.03"/>
      <mass value="0.0"/>
      <inertia ixx="0.0" ixy="0.0" ixz="0.0" iyy="0.0" iyz="0.0" izz="0.0"/>
    </inertial>
    <visual>
      <origin rpy="0.0 1.5707963267948966 0.0" xyz="-0.00075 -0.037 0.03"/>
      <geometry>
        <mesh filename="package://strawberry_picking_rpi_description/meshes/gripper_palm.stl" scale="0.001 0.001 0.001"/>
      </geometry>
      <material name="aluminum"/>
    </visual>
    <collision>
      <origin rpy="0.0 1.5707963267948966 0.0" xyz="-0.00075 -0.037 0.03"/>
      <geometry>
        <mesh filename="package://strawberry_picking_rpi_description/meshes/gripper_palm.stl" scale="0.001 0.001 0.001"/>
      </geometry>
    </collision>
  </link>
  <link name="gripper_palm_to_finger_large_lo">
    <inertial>
      <origin rpy="1.5707963267948966 2.041592653589793 1.5707963267948966" xyz="0.0 0.0 0.0"/>
      <mass value="0.0"/>
      <inertia ixx="0.0" ixy="0.0" ixz="0.0" iyy="0.0" iyz="0.0" izz="0.0"/>
    </inertial>
    <visual>
      <origin rpy="1.5707963267948966 2.041592653589793 1.5707963267948966" xyz="-0.00075 0.0 0.0"/>
      <geometry>
        <mesh filename="package://strawberry_picking_rpi_description/meshes/gripper_palm_to_finger_large_lo.stl" scale="0.001 0.001 0.001"/>
      </geometry>
      <material name="aluminum"/>
    </visual>
  </link>
  <joint name="GRIPPER" type="revolute">
    <parent link="gripper_base"/>
    <child link="gripper_palm_to_finger_large_lo"/>
    <axis xyz="-1 0 0"/>
    <limit effort="1000.0" lower="0.0" upper="1.1" velocity="50.0"/>
    <origin rpy="0 0 0" xyz="-0.002 -0.015 0.03"/>
  </joint>
  <link name="gripper_palm_to_finger_large">
    <inertial>
      <origin rpy="1.5707963267948966 2.041592653589793 1.5707963267948966" xyz="0.0 0.0 0.0"/>
      <mass value="0.0"/>
      <inertia ixx="0.0" ixy="0.0" ixz="0.0" iyy="0.0" iyz="0.0" izz="0.0"/>
    </inertial>
    <visual>
      <origin rpy="1.5707963267948966 2.041592653589793 -1.5707963267948966" xyz="-0.00075 0.0 0.0"/>
      <geometry>
        <mesh filename="package://strawberry_picking_rpi_description/meshes/gripper_palm_to_finger_large.stl" scale="0.001 0.001 0.001"/>
      </geometry>
      <material name="aluminum"/>
    </visual>
  </link>
  <joint name="gripper_palm_to_finger_large_to_gripper_base" type="revolute">
    <parent link="gripper_base"/>
    <child link="gripper_palm_to_finger_large"/>
    <mimic joint="GRIPPER"/>
    <axis xyz="1 0 0"/>
    <limit effort="1000.0" lower="-3.14159" upper="3.14159" velocity="50.0"/>
    <origin rpy="0 0 0" xyz="0.0 0.012 0.03"/>
  </joint>
  <link name="gripper_palm_to_finger_small_left_over">
    <inertial>
      <origin rpy="1.5707963267948966 2.041592653589793 1.5707963267948966" xyz="0.0 0.0 0.0"/>
      <mass value="0.0"/>
      <inertia ixx="0.0" ixy="0.0" ixz="0.0" iyy="0.0" iyz="0.0" izz="0.0"/>
    </inertial>
    <visual>
      <origin rpy="1.5707963267948966 2.041592653589793 -1.5707963267948966" xyz="-0.00075 0.0 0.0"/>
      <geometry>
        <mesh filename="package://strawberry_picking_rpi_description/meshes/gripper_palm_to_finger_small.stl" scale="0.001 0.001 0.001"/>
      </geometry>
      <material name="aluminum"/>
    </visual>
  </link>
  <joint name="gripper_palm_to_finger_small_left_over_to_gripper_base" type="revolute">
    <parent link="gripper_base"/>
    <child link="gripper_palm_to_finger_small_left_over"/>
    <axis xyz="1 0 0"/>
    <mimic joint="GRIPPER"/>
    <limit effort="1000.0" lower="-3.14159" upper="3.14159" velocity="50.0"/>
    <origin rpy="0 0 0" xyz="0.0 0.0068 0.052"/>
  </joint>
  <link name="gripper_palm_to_finger_small_left_under">
    <inertial>
      <origin rpy="1.5707963267948966 2.041592653589793 1.5707963267948966" xyz="0.0 0.0 0.0"/>
      <mass value="0.0"/>
      <inertia ixx="0.0" ixy="0.0" ixz="0.0" iyy="0.0" iyz="0.0" izz="0.0"/>
    </inertial>
    <visual>
      <origin rpy="1.5707963267948966 2.041592653589793 -1.5707963267948966" xyz="-0.00075 0.0 0.0"/>
      <geometry>
        <mesh filename="package://strawberry_picking_rpi_description/meshes/gripper_palm_to_finger_small.stl" scale="0.001 0.001 0.001"/>
      </geometry>
      <material name="aluminum"/>
    </visual>
  </link>
  <joint name="gripper_palm_to_finger_small_left_under_to_gripper_base" type="revolute">
    <parent link="gripper_base"/>
    <child link="gripper_palm_to_finger_small_left_under"/>
    <axis xyz="1 0 0"/>
    <mimic joint="GRIPPER"/>
    <limit effort="1000.0" lower="-3.14159" upper="3.14159" velocity="50.0"/>
    <origin rpy="0 0 0" xyz="0.004 0.0068 0.052"/>
  </joint>
  <link name="gripper_palm_to_finger_small_right_over">
    <inertial>
      <origin rpy="1.5707963267948966 4.241592653589793 1.5707963267948966" xyz="0.0 0.0 0.0"/>
      <mass value="0.0"/>
      <inertia ixx="0.0" ixy="0.0" ixz="0.0" iyy="0.0" iyz="0.0" izz="0.0"/>
    </inertial>
    <visual>
      <origin rpy="1.5707963267948966 4.241592653589793 -1.5707963267948966" xyz="-0.00075 0.0 0.0"/>
      <geometry>
        <mesh filename="package://strawberry_picking_rpi_description/meshes/gripper_palm_to_finger_small.stl" scale="0.001 0.001 0.001"/>
      </geometry>
      <material name="aluminum"/>
    </visual>
  </link>
  <joint name="gripper_palm_to_finger_small_right_over_to_gripper_base" type="revolute">
    <parent link="gripper_base"/>
    <child link="gripper_palm_to_finger_small_right_over"/>
    <axis xyz="1 0 0"/>
    <mimic joint="GRIPPER" multiplier="-1"/>
    <limit effort="1000.0" lower="-3.14159" upper="3.14159" velocity="50.0"/>
    <origin rpy="0 0 0" xyz="0.0 -0.0068 0.052"/>
  </joint>
  <link name="gripper_palm_to_finger_small_right_under">
    <inertial>
      <origin rpy="1.5707963267948966 4.241592653589793 1.5707963267948966" xyz="0.0 0.0 0.0"/>
      <mass value="0.0"/>
      <inertia ixx="0.0" ixy="0.0" ixz="0.0" iyy="0.0" iyz="0.0" izz="0.0"/>
    </inertial>
    <visual>
      <origin rpy="1.5707963267948966 4.241592653589793 -1.5707963267948966" xyz="-0.00075 0.0 0.0"/>
      <geometry>
        <mesh filename="package://strawberry_picking_rpi_description/meshes/gripper_palm_to_finger_small.stl" scale="0.001 0.001 0.001"/>
      </geometry>
      <material name="aluminum"/>
    </visual>
  </link>
  <joint name="gripper_palm_to_finger_small_right_under_to_gripper_base" type="revolute">
    <parent link="gripper_base"/>
    <child link="gripper_palm_to_finger_small_right_under"/>
    <axis xyz="1 0 0"/>
    <mimic joint="GRIPPER" multiplier="-1"/>
    <limit effort="1000.0" lower="-3.14159" upper="3.14159" velocity="50.0"/>
    <origin rpy="0 0 0" xyz="0.004 -0.0068 0.052"/>
  </joint>
  <link name="finger_left">
    <inertial>
      <origin rpy="1.5707963267948966 3.141592653589793 1.5707963267948966" xyz="0.0 0.0 0.0"/>
      <mass value="0.0"/>
      <inertia ixx="0.0" ixy="0.0" ixz="0.0" iyy="0.0" iyz="0.0" izz="0.0"/>
    </inertial>
    <visual>
      <origin rpy="1.5707963267948966 -1.5707963267948966 -1.5707963267948966" xyz="-0.00075 -0.005 -0.005"/>
      <geometry>
        <mesh filename="package://strawberry_picking_rpi_description/meshes/finger.stl" scale="0.001 0.001 0.001"/>
      </geometry>
      <material name="aluminum"/>
    </visual>
    <collision>
      <origin rpy="1.5707963267948966 -1.5707963267948966 -1.5707963267948966" xyz="-0.00075 -0.005 -0.005"/>
      <geometry>
        <mesh filename="package://strawberry_picking_rpi_description/meshes/finger.stl" scale="0.001 0.001 0.001"/>
      </geometry>
    </collision>
  </link>
  <joint name="finger_left_to_gripper_palm_to_finger_large" type="revolute">
    <parent link="gripper_palm_to_finger_large"/>
    <child link="finger_left"/>
    <axis xyz="1 0 0"/>
    <mimic joint="gripper_palm_to_finger_large_to_gripper_base" multiplier="-1"/>
    <limit effort="1000.0" lower="-3.14159" upper="3.14159" velocity="50.0"/>
    <origin rpy="0.34 0 0" xyz="0.002 0.0275 0.01425"/>
  </joint>
  <link name="finger_right">
    <inertial>
      <origin rpy="1.5707963267948966 3.141592653589793 1.5707963267948966" xyz="0.0 0.0 0.0"/>
      <mass value="0.0"/>
      <inertia ixx="0.0" ixy="0.0" ixz="0.0" iyy="0.0" iyz="0.0" izz="0.0"/>
    </inertial>
    <visual>
      <origin rpy="-1.5707963267948966 -1.5707963267948966 -1.5707963267948966" xyz="0.000 0.005 -0.005"/>
      <geometry>
        <mesh filename="package://strawberry_picking_rpi_description/meshes/finger.stl" scale="0.001 0.001 0.001"/>
      </geometry>
      <material name="aluminum"/>
    </visual>
    <collision>
      <origin rpy="-1.5707963267948966 -1.5707963267948966 -1.5707963267948966" xyz="0.000 0.005 -0.005"/>
      <geometry>
        <mesh filename="package://strawberry_picking_rpi_description/meshes/finger.stl" scale="0.001 0.001 0.001"/>
      </geometry>
    </collision>
  </link>
  <joint name="finger_right_to_gripper_palm_to_finger_large" type="revolute">
    <parent link="gripper_palm_to_finger_large_lo"/>
    <child link="finger_right"/>
    <axis xyz="1 0 0"/>
    <mimic joint="gripper_palm_to_finger_large_to_gripper_base"/>
    <limit effort="1000.0" lower="-3.14159" upper="3.14159" velocity="50.0"/>
    <origin rpy="-0.38 0 0" xyz="0.002 -0.0275 0.01425"/>
  </joint>
  <link name="gripper_servo">
    <inertial>
      <origin rpy="1.5707963267948966 3.141592653589793 -1.5707963267948966" xyz="0.0 0.0 0.0"/>
      <mass value="0.0"/>
      <inertia ixx="0.0" ixy="0.0" ixz="0.0" iyy="0.0" iyz="0.0" izz="0.0"/>
    </inertial>
    <visual>
      <origin rpy="1.5707963267948966 3.141592653589793 -1.5707963267948966" xyz="0.0275 -0.0095 0.0"/>
      <geometry>
        <mesh filename="package://strawberry_picking_rpi_description/meshes/mg996r_servo_reversed.stl" scale="0.001 0.001 0.001"/>
      </geometry>
      <material name="aluminum"/>
    </visual>
    <collision>
      <origin rpy="1.5707963267948966 3.141592653589793 -1.5707963267948966" xyz="0.0275 -0.0095 0.0"/>
      <geometry>
        <mesh filename="package://strawberry_picking_rpi_description/meshes/mg996r_servo_reversed.stl" scale="0.001 0.001 0.001"/>
      </geometry>
    </collision>
  </link>
  <joint name="gripper_servo_to_gripper_base" type="fixed">
    <parent link="gripper_base"/>
    <child link="gripper_servo"/>
    <origin rpy="0.0 0 0" xyz="0.002 -0.015 0.0305"/>
  </joint>
  <joint name="DOF_5" type="revolute">
    <parent link="5_multi_functional_servo_bracket_with_servo"/>
    <child link="gripper_base"/>
    <origin rpy="1.5707963267948966 0.0 1.5707963267948966" xyz="0.034 0.012 0.01"/>
    <axis xyz="0.0 0.0 1"/>
    <limit effort="1000" lower="0" upper="3.141592653589793" velocity="6.98133333333"/>
    <axis xyz="0.0 0.0 1"/>
  </joint>
  <!-- ros2_control part, commented out for MoveIt2 -->
  <!--<xacro:include filename="$(find strawberry_picking_rpi_description)/urdf/strawberry_picking_rpi_control.urdf.xacro"/>
    <xacro:controllers/>-->
  <link name="kabaong">
    <inertial>
      <origin rpy="         0.0          0.0         0.0" xyz="         0.0         0.0         0.0"/>
      <mass value="0.0"/>
      <inertia ixx="0.0" ixy="0.0" ixz="0.0" iyy="0.0" iyz="0.0" izz="0.0"/>
    </inertial>
    <visual>
      <origin rpy="         0.0          0.0         0.0" xyz="         0.0         0.0         0.0"/>
      <geometry>
        <box size="0.85                                 0.25                                 0.05"/>
      </geometry>
      <material name="wood"/>
    </visual>
    <collision>
      <origin rpy="         0.0          0.0         0.0" xyz="         0.0         0.0         0.0"/>
      <geometry>
        <box size="0.85                                 0.25                                 0.05"/>
      </geometry>
    </collision>
  </link>
  <joint name="kabaong_to_base_link" type="fixed">
    <origin rpy="         0.0          0.0         0.0" xyz="         0.0         -0.075         -0.035"/>
    <parent link="base_link"/>
    <child link="kabaong"/>
  </joint>
  <link name="basket_diseased">
    <inertial>
      <origin rpy="0.0 0.0 0.0" xyz="0.0 0.0 0.065"/>
      <mass value="0.0"/>
      <inertia ixx="0.0" ixy="0.0" ixz="0.0" iyy="0.0" iyz="0.0" izz="0.0"/>
    </inertial>
    <visual>
      <origin rpy="0.0 0.0 0.0" xyz="0.0 0.0 0.065"/>
      <geometry>
        <cylinder length="0.13" radius="0.085"/>
      </geometry>
      <material name="wood"/>
    </visual>
    <collision>
      <origin rpy="0.0 0.0 0.0" xyz="0.0 0.0 0.065"/>
      <geometry>
        <cylinder length="0.13" radius="0.085"/>
      </geometry>
    </collision>
  </link>
  <joint name="basket_diseased_to_kabaong" type="fixed">
    <origin rpy="             0.0              0.0             0.0" xyz="             -0.36              0.0              0.025"/>
    <parent link="kabaong"/>
    <child link="basket_diseased"/>
  </joint>
  <link name="basket_healthy">
    <inertial>
      <origin rpy="0.0 0.0 0.0" xyz="0.0 0.0 0.065"/>
      <mass value="0.0"/>
      <inertia ixx="0.0" ixy="0.0" ixz="0.0" iyy="0.0" iyz="0.0" izz="0.0"/>
    </inertial>
    <visual>
      <origin rpy="0.0 0.0 0.0" xyz="0.0 0.0 0.065"/>
      <geometry>
        <cylinder length="0.13" radius="0.085"/>
      </geometry>
      <material name="wood"/>
    </visual>
    <collision>
      <origin rpy="0.0 0.0 0.0" xyz="0.0 0.0 0.065"/>
      <geometry>
        <cylinder length="0.13" radius="0.085"/>
      </geometry>
    </collision>
  </link>
  <joint name="basket_healthy_to_kabaong" type="fixed">
    <origin rpy="             0.0              0.0             0.0" xyz="             -0.19              0.0              0.025"/>
    <parent link="kabaong"/>
    <child link="basket_healthy"/>
  </joint>
  <link name="mirror_left">
    <inertial>
      <origin rpy="0.0 0.0 0.0" xyz="0.0 0.0 0.075"/>
      <mass value="0.0"/>
      <inertia ixx="0.0" ixy="0.0" ixz="0.0" iyy="0.0" iyz="0.0" izz="0.0"/>
    </inertial>
    <visual>
      <origin rpy="0.0 0.0 0.0" xyz="0.0 0.0 0.075"/>
      <geometry>
        <box size="0.03                                 0.105                                 0.15"/>
      </geometry>
      <material name="wood"/>
    </visual>
    <collision>
      <origin rpy="0.0 0.0 0.0" xyz="0.0 0.0 0.075"/>
      <geometry>
        <box size="0.03                                 0.105                                 0.15"/>
      </geometry>
    </collision>
  </link>
  <joint name="mirror_left_to_kabaong" type="fixed">
    <origin rpy="             0.0              0.0             -0.602138592" xyz="             0.375              -0.0555             0.025"/>
    <parent link="kabaong"/>
    <child link="mirror_left"/>
  </joint>
  <link name="mirror_right">
    <inertial>
      <origin rpy="0.0 0.0 0.0" xyz="0.0 0.0 0.075"/>
      <mass value="0.0"/>
      <inertia ixx="0.0" ixy="0.0" ixz="0.0" iyy="0.0" iyz="0.0" izz="0.0"/>
    </inertial>
    <visual>
      <origin rpy="0.0 0.0 0.0" xyz="0.0 0.0 0.075"/>
      <geometry>
        <box size="0.03                                 0.105                                 0.15"/>
      </geometry>
      <material name="wood"/>
    </visual>
    <collision>
      <origin rpy="0.0 0.0 0.0" xyz="0.0 0.0 0.075"/>
      <geometry>
        <box size="0.03                                 0.105                                 0.15"/>
      </geometry>
    </collision>
  </link>
  <joint name="mirror_right_to_kabaong" type="fixed">
    <origin rpy="             0.0              0.0             0.602138592" xyz="             0.375              0.0555             0.025"/>
    <parent link="kabaong"/>
    <child link="mirror_right"/>
  </joint>
  <link name="depth_camera_mount">
    <inertial>
      <origin rpy="0.0 0.0 0.0" xyz="0.0 0.0 0.055"/>
      <mass value="0.0"/>
      <inertia ixx="0.0" ixy="0.0" ixz="0.0" iyy="0.0" iyz="0.0" izz="0.0"/>
    </inertial>
    <visual>
      <origin rpy="0.0 0.0 0.0" xyz="0.0 0.0 0.055"/>
      <geometry>
        <box size="0.037                                 0.025                                 0.11"/>
      </geometry>
      <material name="wood"/>
    </visual>
    <collision>
      <origin rpy="0.0 0.0 0.0" xyz="0.0 0.0 0.055"/>
      <geometry>
        <box size="0.037                                 0.025                                 0.11"/>
      </geometry>
    </collision>
  </link>
  <joint name="depth_camera_mount_to_kabaong" type="fixed">
    <origin rpy="             0.0              0.0             0.0" xyz="             0.07650000000000001             0.0475             0.025"/>
    <parent link="kabaong"/>
    <child link="depth_camera_mount"/>
  </joint>
  <link name="mirror_camera_mount">
    <inertial>
      <origin rpy="0.0 0.0 0.0" xyz="0.0 0.0 0.031"/>
      <mass value="0.0"/>
      <inertia ixx="0.0" ixy="0.0" ixz="0.0" iyy="0.0" iyz="0.0" izz="0.0"/>
    </inertial>
    <visual>
      <origin rpy="0.0 0.0 0.0" xyz="0.0 0.0 0.031"/>
      <geometry>
        <box size="0.037                                 0.025                                 0.062"/>
      </geometry>
      <material name="wood"/>
    </visual>
    <collision>
      <origin rpy="0.0 0.0 0.0" xyz="0.0 0.0 0.031"/>
      <geometry>
        <box size="0.037                                 0.025                                 0.062"/>
      </geometry>
    </collision>
  </link>
  <joint name="mirror_camera_mount_to_kabaong" type="fixed">
    <origin rpy="             0.0              0.0             1.5707963267948966" xyz="             0.07650000000000001             0.012499999999999997             0.025"/>
    <parent link="kabaong"/>
    <child link="mirror_camera_mount"/>
  </joint>
  <link name="mirror_camera">
    <visual>
      <origin rpy="0.0 0.0 -3.141592653589793" xyz="0.0125 0.0145 0.0"/>
      <geometry>
        <mesh filename="package://strawberry_picking_rpi_description/meshes/Pi Camera Module v3.STL" scale="0.001 0.001 0.001"/>
      </geometry>
      <material name="black_plastic"/>
    </visual>
  </link>
  <joint name="mirror_camera_to_mirror_camera_mount" type="fixed">
    <origin rpy="             1.5707963267948966             0.0             0.0" xyz="             0.0             -0.0125             0.041999999999999996"/>
    <parent link="mirror_camera_mount"/>
    <child link="mirror_camera"/>
  </joint>
  <link name="depth_camera">
    <visual>
      <origin rpy="0.0 0.0 -3.141592653589793" xyz="0.0125 0.0145 0.0"/>
      <geometry>
        <mesh filename="package://strawberry_picking_rpi_description/meshes/Pi Camera Module v3.STL" scale="0.001 0.001 0.001"/>
      </geometry>
      <material name="black_plastic"/>
    </visual>
  </link>
  <joint name="depth_camera_to_depth_camera_mount" type="fixed">
    <origin rpy="             1.5707963267948966             0.0             0.0" xyz="             0.0             -0.0125             0.09"/>
    <parent link="depth_camera_mount"/>
    <child link="depth_camera"/>
  </joint>
</robot>
